<?xml version="1.0"?>
<robot xmlns:xacro="http://www.ros.org/wiki/xacro" name="amr_robot">
  
  <!-- Robot Properties -->
  <xacro:property name="wheel_radius" value="0.05"/>
  <xacro:property name="wheel_width" value="0.04"/>
  <xacro:property name="wheel_separation" value="0.3"/>
  <xacro:property name="chassis_length" value="0.4"/>
  <xacro:property name="chassis_width" value="0.3"/>
  <xacro:property name="chassis_height" value="0.15"/>
  <xacro:property name="caster_radius" value="0.02"/>
  
  <!-- Colors -->
  <material name="blue">
    <color rgba="0.2 0.2 0.8 1.0"/>
  </material>
  <material name="black">
    <color rgba="0.1 0.1 0.1 1.0"/>
  </material>
  <material name="white">
    <color rgba="0.9 0.9 0.9 1.0"/>
  </material>
  <material name="orange">
    <color rgba="1.0 0.5 0.0 1.0"/>
  </material>

  <!-- Base Footprint -->
  <link name="base_footprint"/>

  <!-- Base Link -->
  <link name="base_link">
    <visual>
      <geometry>
        <box size="${chassis_length} ${chassis_width} ${chassis_height}"/>
      </geometry>
      <origin xyz="0 0 ${chassis_height/2 + wheel_radius}" rpy="0 0 0"/>
      <material name="orange"/>
    </visual>
    <collision>
      <geometry>
        <box size="${chassis_length} ${chassis_width} ${chassis_height}"/>
      </geometry>
      <origin xyz="0 0 ${chassis_height/2 + wheel_radius}" rpy="0 0 0"/>
    </collision>
    <inertial>
      <mass value="5.0"/>
      <origin xyz="0 0 ${chassis_height/2 + wheel_radius}" rpy="0 0 0"/>
      <inertia ixx="0.05" ixy="0.0" ixz="0.0" iyy="0.1" iyz="0.0" izz="0.1"/>
    </inertial>
  </link>

  <joint name="base_joint" type="fixed">
    <parent link="base_footprint"/>
    <child link="base_link"/>
    <origin xyz="0 0 0" rpy="0 0 0"/>
  </joint>

  <!-- Wheel Macro -->
  <xacro:macro name="wheel" params="prefix y_offset">
    <link name="${prefix}_wheel">
      <visual>
        <geometry>
          <cylinder radius="${wheel_radius}" length="${wheel_width}"/>
        </geometry>
        <origin xyz="0 0 0" rpy="${pi/2} 0 0"/>
        <material name="black"/>
      </visual>
      <collision>
        <geometry>
          <cylinder radius="${wheel_radius}" length="${wheel_width}"/>
        </geometry>
        <origin xyz="0 0 0" rpy="${pi/2} 0 0"/>
      </collision>
      <inertial>
        <mass value="0.5"/>
        <origin xyz="0 0 0" rpy="${pi/2} 0 0"/>
        <inertia ixx="0.001" ixy="0.0" ixz="0.0" iyy="0.001" iyz="0.0" izz="0.001"/>
      </inertial>
    </link>

    <joint name="${prefix}_wheel_joint" type="continuous">
      <parent link="base_link"/>
      <child link="${prefix}_wheel"/>
      <origin xyz="0 ${y_offset} ${wheel_radius}" rpy="0 0 0"/>
      <axis xyz="0 1 0"/>
      <dynamics damping="0.1" friction="0.1"/>
    </joint>
  </xacro:macro>

  <!-- Left and Right Wheels -->
  <xacro:wheel prefix="left" y_offset="${wheel_separation/2}"/>
  <xacro:wheel prefix="right" y_offset="${-wheel_separation/2}"/>

  <!-- Front Caster -->
  <link name="front_caster">
    <visual>
      <geometry>
        <sphere radius="${caster_radius}"/>
      </geometry>
      <material name="white"/>
    </visual>
    <collision>
      <geometry>
        <sphere radius="${caster_radius}"/>
      </geometry>
    </collision>
    <inertial>
      <mass value="0.1"/>
      <inertia ixx="0.0001" ixy="0.0" ixz="0.0" iyy="0.0001" iyz="0.0" izz="0.0001"/>
    </inertial>
  </link>

  <joint name="front_caster_joint" type="fixed">
    <parent link="base_link"/>
    <child link="front_caster"/>
    <origin xyz="${chassis_length/2 - 0.05} 0 ${caster_radius}" rpy="0 0 0"/>
  </joint>

  <!-- Rear Caster -->
  <link name="rear_caster">
    <visual>
      <geometry>
        <sphere radius="${caster_radius}"/>
      </geometry>
      <material name="white"/>
    </visual>
    <collision>
      <geometry>
        <sphere radius="${caster_radius}"/>
      </geometry>
    </collision>
    <inertial>
      <mass value="0.1"/>
      <inertia ixx="0.0001" ixy="0.0" ixz="0.0" iyy="0.0001" iyz="0.0" izz="0.0001"/>
    </inertial>
  </link>

  <joint name="rear_caster_joint" type="fixed">
    <parent link="base_link"/>
    <child link="rear_caster"/>
    <origin xyz="${-chassis_length/2 + 0.05} 0 ${caster_radius}" rpy="0 0 0"/>
  </joint>

  <!-- Lidar Link -->
  <link name="lidar_link">
    <visual>
      <geometry>
        <cylinder radius="0.05" length="0.04"/>
      </geometry>
      <material name="blue"/>
    </visual>
    <collision>
      <geometry>
        <cylinder radius="0.05" length="0.04"/>
      </geometry>
    </collision>
    <inertial>
      <mass value="0.2"/>
      <inertia ixx="0.0001" ixy="0.0" ixz="0.0" iyy="0.0001" iyz="0.0" izz="0.0001"/>
    </inertial>
  </link>

  <joint name="lidar_joint" type="fixed">
    <parent link="base_link"/>
    <child link="lidar_link"/>
    <origin xyz="0 0 ${chassis_height + wheel_radius + 0.02}" rpy="0 0 0"/>
  </joint>

  <!-- IMU Link -->
  <link name="imu_link">
    <visual>
      <geometry>
        <box size="0.02 0.02 0.01"/>
      </geometry>
      <material name="blue"/>
    </visual>
  </link>

  <joint name="imu_joint" type="fixed">
    <parent link="base_link"/>
    <child link="imu_link"/>
    <origin xyz="0 0 ${chassis_height + wheel_radius}" rpy="0 0 0"/>
  </joint>

  <!-- Gazebo Plugins -->
  <gazebo>
    <plugin name="diff_drive" filename="libgazebo_ros_diff_drive.so">
      <ros>
        <namespace>/</namespace>
      </ros>
      
      <left_joint>left_wheel_joint</left_joint>
      <right_joint>right_wheel_joint</right_joint>
      
      <wheel_separation>${wheel_separation}</wheel_separation>
      <wheel_diameter>${wheel_radius * 2}</wheel_diameter>
      
      <max_wheel_torque>20</max_wheel_torque>
      <max_wheel_acceleration>1.0</max_wheel_acceleration>
      
      <command_topic>cmd_vel</command_topic>
      <odometry_topic>odom</odometry_topic>
      <odometry_frame>odom</odometry_frame>
      <robot_base_frame>base_footprint</robot_base_frame>
      
      <publish_odom>true</publish_odom>
      <publish_odom_tf>true</publish_odom_tf>
      <publish_wheel_tf>true</publish_wheel_tf>
      
      <update_rate>50</update_rate>
    </plugin>
  </gazebo>

  <!-- Gazebo Lidar Plugin -->
  <gazebo reference="lidar_link">
    <sensor name="lidar" type="ray">
      <always_on>true</always_on>
      <visualize>true</visualize>
      <update_rate>10</update_rate>
      <ray>
        <scan>
          <horizontal>
            <samples>360</samples>
            <resolution>1</resolution>
            <min_angle>-3.14159</min_angle>
            <max_angle>3.14159</max_angle>
          </horizontal>
        </scan>
        <range>
          <min>0.12</min>
          <max>12.0</max>
          <resolution>0.01</resolution>
        </range>
        <noise>
          <type>gaussian</type>
          <mean>0.0</mean>
          <stddev>0.01</stddev>
        </noise>
      </ray>
      <plugin name="scan" filename="libgazebo_ros_ray_sensor.so">
        <ros>
          <remapping>~/out:=scan</remapping>
        </ros>
        <output_type>sensor_msgs/LaserScan</output_type>
        <frame_name>lidar_link</frame_name>
      </plugin>
    </sensor>
    <material>Gazebo/Blue</material>
  </gazebo>

  <!-- Gazebo IMU Plugin -->
  <gazebo reference="imu_link">
    <sensor name="imu_sensor" type="imu">
      <always_on>true</always_on>
      <update_rate>100</update_rate>
      <plugin name="imu_plugin" filename="libgazebo_ros_imu_sensor.so">
        <ros>
          <remapping>~/out:=imu</remapping>
        </ros>
        <initial_orientation_as_reference>false</initial_orientation_as_reference>
        <frame_name>imu_link</frame_name>
      </plugin>
    </sensor>
  </gazebo>

  <!-- Gazebo Colors -->
  <gazebo reference="base_link">
    <material>Gazebo/Orange</material>
  </gazebo>
  <gazebo reference="left_wheel">
    <material>Gazebo/Black</material>
    <mu1>1.0</mu1>
    <mu2>1.0</mu2>
  </gazebo>
  <gazebo reference="right_wheel">
    <material>Gazebo/Black</material>
    <mu1>1.0</mu1>
    <mu2>1.0</mu2>
  </gazebo>
  <gazebo reference="front_caster">
    <material>Gazebo/White</material>
    <mu1>0.0</mu1>
    <mu2>0.0</mu2>
  </gazebo>
  <gazebo reference="rear_caster">
    <material>Gazebo/White</material>
    <mu1>0.0</mu1>
    <mu2>0.0</mu2>
  </gazebo>

</robot>
